<?xml version="1.0" ?>
<!-- =================================================================================== -->
<!-- |    This document was autogenerated by xacro from ugv.xacro                      | -->
<!-- |    EDITING THIS FILE BY HAND IS NOT RECOMMENDED                                 | -->
<!-- =================================================================================== -->
<robot name="ugv">
  <material name="silver">
    <color rgba="0.700 0.700 0.700 1.000"/>
  </material>
  <transmission name="left_steering_tran">
    <type>transmission_interface/SimpleTransmission</type>
    <joint name="left_steering">
      <hardwareInterface>hardware_interface/EffortJointInterface</hardwareInterface>
    </joint>
    <actuator name="left_steering_actr">
      <hardwareInterface>hardware_interface/EffortJointInterface</hardwareInterface>
      <mechanicalReduction>1</mechanicalReduction>
    </actuator>
  </transmission>
  <transmission name="right_steering_tran">
    <type>transmission_interface/SimpleTransmission</type>
    <joint name="right_steering">
      <hardwareInterface>hardware_interface/EffortJointInterface</hardwareInterface>
    </joint>
    <actuator name="right_steering_actr">
      <hardwareInterface>hardware_interface/EffortJointInterface</hardwareInterface>
      <mechanicalReduction>1</mechanicalReduction>
    </actuator>
  </transmission>
  <transmission name="front_left_wheel_tran">
    <type>transmission_interface/SimpleTransmission</type>
    <joint name="front_left_wheel">
      <hardwareInterface>hardware_interface/EffortJointInterface</hardwareInterface>
    </joint>
    <actuator name="front_left_wheel_actr">
      <hardwareInterface>hardware_interface/EffortJointInterface</hardwareInterface>
      <mechanicalReduction>1</mechanicalReduction>
    </actuator>
  </transmission>
  <transmission name="front_right_wheel_tran">
    <type>transmission_interface/SimpleTransmission</type>
    <joint name="front_right_wheel">
      <hardwareInterface>hardware_interface/EffortJointInterface</hardwareInterface>
    </joint>
    <actuator name="front_right_wheel_actr">
      <hardwareInterface>hardware_interface/EffortJointInterface</hardwareInterface>
      <mechanicalReduction>1</mechanicalReduction>
    </actuator>
  </transmission>
  <transmission name="back_left_wheel_tran">
    <type>transmission_interface/SimpleTransmission</type>
    <joint name="back_left_wheel">
      <hardwareInterface>hardware_interface/EffortJointInterface</hardwareInterface>
    </joint>
    <actuator name="back_left_wheel_actr">
      <hardwareInterface>hardware_interface/EffortJointInterface</hardwareInterface>
      <mechanicalReduction>1</mechanicalReduction>
    </actuator>
  </transmission>
  <transmission name="back_right_wheel_tran">
    <type>transmission_interface/SimpleTransmission</type>
    <joint name="back_right_wheel">
      <hardwareInterface>hardware_interface/EffortJointInterface</hardwareInterface>
    </joint>
    <actuator name="back_right_wheel_actr">
      <hardwareInterface>hardware_interface/EffortJointInterface</hardwareInterface>
      <mechanicalReduction>1</mechanicalReduction>
    </actuator>
  </transmission>
  <gazebo>
    <plugin filename="libgazebo_ros_control.so" name="control"/>
  </gazebo>
  <gazebo reference="base_link">
    <material>Gazebo/Silver</material>
    <mu1>0.2</mu1>
    <mu2>0.2</mu2>
    <self_collide>true</self_collide>
    <gravity>true</gravity>
  </gazebo>
  <gazebo reference="RightSupport_v1_1">
    <material>Gazebo/Silver</material>
    <mu1>0.2</mu1>
    <mu2>0.2</mu2>
    <self_collide>true</self_collide>
  </gazebo>
  <gazebo reference="LeftSupport_v1_1">
    <material>Gazebo/Silver</material>
    <mu1>0.2</mu1>
    <mu2>0.2</mu2>
    <self_collide>true</self_collide>
  </gazebo>
  <gazebo reference="Mounting_Plate_v3_v1_1">
    <material>Gazebo/Silver</material>
    <mu1>0.2</mu1>
    <mu2>0.2</mu2>
    <self_collide>true</self_collide>
  </gazebo>
  <gazebo reference="Mounting_Plate_v3_v1__1__1">
    <material>Gazebo/Silver</material>
    <mu1>0.2</mu1>
    <mu2>0.2</mu2>
    <self_collide>true</self_collide>
  </gazebo>
  <gazebo reference="FrontCover_v1_1">
    <material>Gazebo/Silver</material>
    <mu1>0.2</mu1>
    <mu2>0.2</mu2>
    <self_collide>true</self_collide>
  </gazebo>
  <gazebo reference="CubeFC_v1_1">
    <material>Gazebo/Silver</material>
    <mu1>0.2</mu1>
    <mu2>0.2</mu2>
    <self_collide>true</self_collide>
  </gazebo>
  <gazebo reference="FrontMountFull_v1_1">
    <material>Gazebo/Silver</material>
    <mu1>0.2</mu1>
    <mu2>0.2</mu2>
    <self_collide>true</self_collide>
  </gazebo>
  <gazebo reference="FrontLight_v1_1">
    <material>Gazebo/Silver</material>
    <mu1>0.2</mu1>
    <mu2>0.2</mu2>
    <self_collide>true</self_collide>
  </gazebo>
  <gazebo reference="FrontLight_v1__1__1">
    <material>Gazebo/Silver</material>
    <mu1>0.2</mu1>
    <mu2>0.2</mu2>
    <self_collide>true</self_collide>
  </gazebo>
  <gazebo reference="Speaker_v1__1__1">
    <material>Gazebo/Silver</material>
    <mu1>0.2</mu1>
    <mu2>0.2</mu2>
    <self_collide>true</self_collide>
  </gazebo>
  <gazebo reference="Speaker_v1_1">
    <material>Gazebo/Silver</material>
    <mu1>0.2</mu1>
    <mu2>0.2</mu2>
    <self_collide>true</self_collide>
  </gazebo>
  <gazebo reference="JetsonCaseBottom_v1_1">
    <material>Gazebo/Silver</material>
    <mu1>0.2</mu1>
    <mu2>0.2</mu2>
    <self_collide>true</self_collide>
  </gazebo>
  <gazebo reference="KeyHolders_v3_v1_1">
    <material>Gazebo/Silver</material>
    <mu1>0.2</mu1>
    <mu2>0.2</mu2>
    <self_collide>true</self_collide>
  </gazebo>
  <gazebo reference="3ButtonMount_v1_1">
    <material>Gazebo/Silver</material>
    <mu1>0.2</mu1>
    <mu2>0.2</mu2>
    <self_collide>true</self_collide>
  </gazebo>
  <gazebo reference="RFD900urdf_v1_1">
    <material>Gazebo/Silver</material>
    <mu1>0.2</mu1>
    <mu2>0.2</mu2>
    <self_collide>true</self_collide>
  </gazebo>
  <gazebo reference="RFDAntenna_v1__1__1">
    <material>Gazebo/Silver</material>
    <mu1>0.2</mu1>
    <mu2>0.2</mu2>
    <self_collide>true</self_collide>
  </gazebo>
  <gazebo reference="RFDAntenna_v1_1">
    <material>Gazebo/Silver</material>
    <mu1>0.2</mu1>
    <mu2>0.2</mu2>
    <self_collide>true</self_collide>
  </gazebo>
  <gazebo reference="MountingClipFinal_v1_1">
    <material>Gazebo/Silver</material>
    <mu1>0.2</mu1>
    <mu2>0.2</mu2>
    <self_collide>true</self_collide>
  </gazebo>
  <gazebo reference="MountingClipFinal_v1__2__1">
    <material>Gazebo/Silver</material>
    <mu1>0.2</mu1>
    <mu2>0.2</mu2>
    <self_collide>true</self_collide>
  </gazebo>
  <gazebo reference="MountingClipFinal_v1__1__1">
    <material>Gazebo/Silver</material>
    <mu1>0.2</mu1>
    <mu2>0.2</mu2>
    <self_collide>true</self_collide>
  </gazebo>
  <gazebo reference="MountingClipFinal_v1__3__1">
    <material>Gazebo/Silver</material>
    <mu1>0.2</mu1>
    <mu2>0.2</mu2>
    <self_collide>true</self_collide>
  </gazebo>
  <gazebo reference="Anker_737_Power_Bank_v2_1">
    <material>Gazebo/Silver</material>
    <mu1>0.2</mu1>
    <mu2>0.2</mu2>
    <self_collide>true</self_collide>
  </gazebo>
  <gazebo reference="Insta360MountwithLidar_v1_1">
    <material>Gazebo/Silver</material>
    <mu1>0.2</mu1>
    <mu2>0.2</mu2>
    <self_collide>true</self_collide>
  </gazebo>
  <gazebo reference="360Cam_v4_1">
    <material>Gazebo/Silver</material>
    <mu1>0.2</mu1>
    <mu2>0.2</mu2>
    <self_collide>true</self_collide>
  </gazebo>
  <gazebo reference="RPLidarC1_v1_1">
    <material>Gazebo/Silver</material>
    <mu1>0.2</mu1>
    <mu2>0.2</mu2>
    <self_collide>true</self_collide>
  </gazebo>
  <gazebo reference="Chassis_1">
    <material>Gazebo/Silver</material>
    <mu1>0.2</mu1>
    <mu2>0.2</mu2>
    <self_collide>true</self_collide>
  </gazebo>
  <gazebo reference="Jetson_Nano_v1_1">
    <material>Gazebo/Silver</material>
    <mu1>0.2</mu1>
    <mu2>0.2</mu2>
    <self_collide>true</self_collide>
  </gazebo>
  <gazebo reference="JetsonCaseTop_v1_1">
    <material>Gazebo/Silver</material>
    <mu1>0.2</mu1>
    <mu2>0.2</mu2>
    <self_collide>true</self_collide>
  </gazebo>
  <gazebo reference="LIPOBattery_v2_1">
    <material>Gazebo/Silver</material>
    <mu1>0.2</mu1>
    <mu2>0.2</mu2>
    <self_collide>true</self_collide>
  </gazebo>
  <gazebo reference="TOFSensor_v3_1">
    <material>Gazebo/Silver</material>
    <mu1>0.2</mu1>
    <mu2>0.2</mu2>
    <self_collide>true</self_collide>
  </gazebo>
  <gazebo reference="LeftHub_1">
    <material>Gazebo/Silver</material>
    <mu1>0.2</mu1>
    <mu2>0.2</mu2>
    <self_collide>true</self_collide>
  </gazebo>
  <gazebo reference="RightHub__1">
    <material>Gazebo/Silver</material>
    <mu1>0.2</mu1>
    <mu2>0.2</mu2>
    <self_collide>true</self_collide>
  </gazebo>
  <gazebo reference="FrontLeft_1">
    <material>Gazebo/Silver</material>
    <mu1>0.2</mu1>
    <mu2>0.2</mu2>
    <self_collide>true</self_collide>
  </gazebo>
  <gazebo reference="FrontRight_1">
    <material>Gazebo/Silver</material>
    <mu1>0.2</mu1>
    <mu2>0.2</mu2>
    <self_collide>true</self_collide>
  </gazebo>
  <gazebo reference="BackLeft_1">
    <material>Gazebo/Silver</material>
    <mu1>0.2</mu1>
    <mu2>0.2</mu2>
    <self_collide>true</self_collide>
  </gazebo>
  <gazebo reference="BackRight_1">
    <material>Gazebo/Silver</material>
    <mu1>0.2</mu1>
    <mu2>0.2</mu2>
    <self_collide>true</self_collide>
  </gazebo>
  <gazebo reference="GPSMount__1__v1_1">
    <material>Gazebo/Silver</material>
    <mu1>0.2</mu1>
    <mu2>0.2</mu2>
    <self_collide>true</self_collide>
  </gazebo>
  <gazebo reference="GPS_v1_1">
    <material>Gazebo/Silver</material>
    <mu1>0.2</mu1>
    <mu2>0.2</mu2>
    <self_collide>true</self_collide>
  </gazebo>
  <!-- Robot Footprint -->
  <link name="base_footprint"/>
  <joint name="base_joint" type="fixed">
    <parent link="base_footprint"/>
    <child link="base_link"/>
    <origin rpy="0 0 0" xyz="-0.075 0.075 0.28375"/>
  </joint>
  <link name="base_link">
    <inertial>
      <origin rpy="0 0 0" xyz="0.0 0.0 0.0"/>
      <mass value="8.5"/>
      <inertia ixx="0.05" ixy="0.0" ixz="0.0" iyy="0.05" iyz="0.0" izz="0.08"/>
    </inertial>
    <visual>
      <origin rpy="0 0 0" xyz="0 0 0"/>
      <geometry>
        <mesh filename="file:///home/odinroast/Desktop/ros2_ws/install/ugv_description/share/ugv_description/meshes/base_link.stl" scale="0.001 0.001 0.001"/>
      </geometry>
      <material name="silver"/>
    </visual>
    <collision>
      <origin rpy="0 0 0" xyz="0.095 -0.075 -0.14"/>
      <geometry>
        <box size="0.40 0.15 0.15"/>
      </geometry>
    </collision>
  </link>
  <link name="RightSupport_v1_1">
    <inertial>
      <origin rpy="0 0 0" xyz="0.07059984434936706 -0.0029361126231948476 -0.05717627321515905"/>
      <mass value="0.736158308473094"/>
      <inertia ixx="0.001003" ixy="9e-06" ixz="5.4e-05" iyy="0.003358" iyz="-4e-06" izz="0.002373"/>
    </inertial>
    <visual>
      <origin rpy="0 0 0" xyz="-0.0075 0.1425 0.000125"/>
      <geometry>
        <mesh filename="file:///home/odinroast/Desktop/ros2_ws/install/ugv_description/share/ugv_description/meshes/RightSupport_v1_1.stl" scale="0.001 0.001 0.001"/>
      </geometry>
      <material name="silver"/>
    </visual>
    <collision>
      <origin rpy="0 0 0" xyz="0.08 -0.07 -0.04"/>
      <geometry>
        <box size="0.20 0.01 0.08"/>
      </geometry>
    </collision>
  </link>
  <link name="LeftSupport_v1_1">
    <inertial>
      <origin rpy="0 0 0" xyz="0.07059984434936703 0.002936112623194766 -0.05717627321515946"/>
      <mass value="0.7361583084730937"/>
      <inertia ixx="0.001003" ixy="-9e-06" ixz="5.4e-05" iyy="0.003358" iyz="4e-06" izz="0.002373"/>
    </inertial>
    <visual>
      <origin rpy="0 0 0" xyz="-0.0075 0.0075 0.000125"/>
      <geometry>
        <mesh filename="file:///home/odinroast/Desktop/ros2_ws/install/ugv_description/share/ugv_description/meshes/LeftSupport_v1_1.stl" scale="0.001 0.001 0.001"/>
      </geometry>
      <material name="silver"/>
    </visual>
    <collision>
      <origin rpy="0 0 0" xyz="0.08 -0.07 -0.04"/>
      <geometry>
        <box size="0.20 0.01 0.08"/>
      </geometry>
    </collision>
  </link>
  <link name="Mounting_Plate_v3_v1_1">
    <inertial>
      <origin rpy="0 0 0" xyz="0.06749999995669587 0.06749999999999994 0.0007876040969322512"/>
      <mass value="0.2720807790827568"/>
      <inertia ixx="0.00051" ixy="0.0" ixz="-0.0" iyy="0.00051" iyz="-0.0" izz="0.001021"/>
    </inertial>
    <visual>
      <origin rpy="0 0 0" xyz="-0.1595 0.1425 0.07325"/>
      <geometry>
        <mesh filename="file:///home/odinroast/Desktop/ros2_ws/install/ugv_description/share/ugv_description/meshes/Mounting_Plate_v3_v1_1.stl" scale="0.001 0.001 0.001"/>
      </geometry>
      <material name="silver"/>
    </visual>
    <collision>
      <origin rpy="0 0 0" xyz="0 0 0"/>
      <geometry>
        <box size="0.27 0.27 0.003"/>
      </geometry>
    </collision>
  </link>
  <link name="Mounting_Plate_v3_v1__1__1">
    <inertial>
      <origin rpy="0 0 0" xyz="-0.06751639011574447 0.06751019132451663 -0.000787199999999974"/>
      <mass value="0.2721394685220584"/>
      <inertia ixx="0.00051" ixy="0.0" ixz="0.0" iyy="0.000511" iyz="-0.0" izz="0.001021"/>
    </inertial>
    <visual>
      <origin rpy="0 0 0" xyz="0.0345 0.1425 0.077325"/>
      <geometry>
        <mesh filename="file:///home/odinroast/Desktop/ros2_ws/install/ugv_description/share/ugv_description/meshes/Mounting_Plate_v3_v1__1__1.stl" scale="0.001 0.001 0.001"/>
      </geometry>
      <material name="silver"/>
    </visual>
        <collision>
      <origin rpy="0 0 0" xyz="0 0 0"/>
      <geometry>
        <box size="0.27 0.27 0.003"/>
      </geometry>
    </collision>
  </link>
  <link name="FrontCover_v1_1">
    <inertial>
      <origin rpy="0 0 0" xyz="0.013768274332071867 3.469446951953614e-16 -0.03192263359636471"/>
      <mass value="0.1610650752657614"/>
      <inertia ixx="0.00056" ixy="-0.0" ixz="3.5e-05" iyy="0.000104" iyz="0.0" izz="0.000484"/>
    </inertial>
    <visual>
      <origin rpy="0 0 0" xyz="-0.15 0.075 -0.00145"/>
      <geometry>
        <mesh filename="file:///home/odinroast/Desktop/ros2_ws/install/ugv_description/share/ugv_description/meshes/FrontCover_v1_1.stl" scale="0.001 0.001 0.001"/>
      </geometry>
      <material name="silver"/>
    </visual>
        <collision>
      <origin rpy="0 0 0" xyz="0 0 0"/>
      <geometry>
        <box size="0.15 0.15 0.003"/>
      </geometry>
    </collision>
  </link>
  <link name="CubeFC_v1_1">
    <inertial>
      <origin rpy="0 0 0" xyz="-0.0014080199813744643 9.577973379054638e-06 -0.007821832207682039"/>
      <mass value="0.1604759232839487"/>
      <inertia ixx="4.6e-05" ixy="0.0" ixz="-3e-06" iyy="0.000125" iyz="-0.0" izz="0.000153"/>
    </inertial>
    <visual>
      <origin rpy="0 0 0" xyz="-0.0975 0.1125 0.000125"/>
      <geometry>
        <mesh filename="file:///home/odinroast/Desktop/ros2_ws/install/ugv_description/share/ugv_description/meshes/CubeFC_v1_1.stl" scale="0.001 0.001 0.001"/>
      </geometry>
      <material name="silver"/>
    </visual>
        <collision>
      <origin rpy="0 0 0" xyz="0 0 0"/>
      <geometry>
        <box size="0.04 0.04 0.02"/>
      </geometry>
    </collision>
  </link>
  <link name="FrontMountFull_v1_1">
    <inertial>
      <origin rpy="0 0 0" xyz="0.0279580578284907 -0.05375006604773858 -0.008637150125757026"/>
      <mass value="0.28337732555839074"/>
      <inertia ixx="0.000749" ixy="-0.0" ixz="3.2e-05" iyy="7.6e-05" iyz="-0.0" izz="0.000737"/>
    </inertial>
    <visual>
      <origin rpy="0 0 0" xyz="-0.2795 0.0225 0.07325"/>
      <geometry>
        <mesh filename="file:///home/odinroast/Desktop/ros2_ws/install/ugv_description/share/ugv_description/meshes/FrontMountFull_v1_1.stl" scale="0.001 0.001 0.001"/>
      </geometry>
      <material name="silver"/>
    </visual>
        <collision>
      <origin rpy="0 0 0" xyz="0 0 0"/>
      <geometry>
        <box size="0.08 0.135 0.02"/>
      </geometry>
    </collision>
  </link>
  <link name="FrontLight_v1_1">
    <inertial>
      <origin rpy="0 0 0" xyz="0.0008376443155606594 -4.214513980860257e-11 0.0005464825713972082"/>
      <mass value="0.0035944139646964697"/>
      <inertia ixx="0.0" ixy="0.0" ixz="0.0" iyy="0.0" iyz="-0.0" izz="0.0"/>
    </inertial>
    <visual>
      <origin rpy="0 0 0" xyz="-0.303776 0.00875 0.072039"/>
      <geometry>
        <mesh filename="file:///home/odinroast/Desktop/ros2_ws/install/ugv_description/share/ugv_description/meshes/FrontLight_v1_1.stl" scale="0.001 0.001 0.001"/>
      </geometry>
      <material name="silver"/>
    </visual>
    
  </link>
  <link name="FrontLight_v1__1__1">
    <inertial>
      <origin rpy="0 0 0" xyz="0.0008376443155604374 -4.214514848221995e-11 0.0005464825713972637"/>
      <mass value="0.0035944139646964697"/>
      <inertia ixx="0.0" ixy="-0.0" ixz="0.0" iyy="0.0" iyz="0.0" izz="0.0"/>
    </inertial>
    <visual>
      <origin rpy="0 0 0" xyz="-0.303776 0.14375 0.072039"/>
      <geometry>
        <mesh filename="file:///home/odinroast/Desktop/ros2_ws/install/ugv_description/share/ugv_description/meshes/FrontLight_v1__1__1.stl" scale="0.001 0.001 0.001"/>
      </geometry>
      <material name="silver"/>
    </visual>
    
  </link>
  <link name="Speaker_v1__1__1">
    <inertial>
      <origin rpy="0 0 0" xyz="-0.0018409431685812994 -0.018474000102515965 -0.0007080958537002691"/>
      <mass value="0.10222453174351626"/>
      <inertia ixx="1.4e-05" ixy="0.0" ixz="3e-06" iyy="1e-05" iyz="-0.0" izz="1.2e-05"/>
    </inertial>
    <visual>
      <origin rpy="0 0 0" xyz="-0.305098 0.031776 0.090129"/>
      <geometry>
        <mesh filename="file:///home/odinroast/Desktop/ros2_ws/install/ugv_description/share/ugv_description/meshes/Speaker_v1__1__1.stl" scale="0.001 0.001 0.001"/>
      </geometry>
      <material name="silver"/>
    </visual>
    
  </link>
  <link name="Speaker_v1_1">
    <inertial>
      <origin rpy="0 0 0" xyz="-0.001840943168581466 0.018473999897483773 -0.0007080958537002691"/>
      <mass value="0.10222453174351626"/>
      <inertia ixx="1.4e-05" ixy="0.0" ixz="3e-06" iyy="1e-05" iyz="-0.0" izz="1.2e-05"/>
    </inertial>
    <visual>
      <origin rpy="0 0 0" xyz="-0.305098 0.120724 0.090129"/>
      <geometry>
        <mesh filename="file:///home/odinroast/Desktop/ros2_ws/install/ugv_description/share/ugv_description/meshes/Speaker_v1_1.stl" scale="0.001 0.001 0.001"/>
      </geometry>
      <material name="silver"/>
    </visual>
    
  </link>
  <link name="JetsonCaseBottom_v1_1">
    <inertial>
      <origin rpy="0 0 0" xyz="0.0008375000953675105 0.0006130909919737915 0.0020196844512747336"/>
      <mass value="0.3621318554388684"/>
      <inertia ixx="0.000384" ixy="-0.0" ixz="0.0" iyy="0.000313" iyz="0.0" izz="0.000696"/>
    </inertial>
    <visual>
      <origin rpy="0 0 0" xyz="0.0945 0.0975 0.077325"/>
      <geometry>
        <mesh filename="file:///home/odinroast/Desktop/ros2_ws/install/ugv_description/share/ugv_description/meshes/JetsonCaseBottom_v1_1.stl" scale="0.001 0.001 0.001"/>
      </geometry>
      <material name="silver"/>
    </visual>
        <collision>
      <origin rpy="0 0 0" xyz="0 0 0"/>
      <geometry>
        <box size="0.10 0.06 0.02"/>
      </geometry>
    </collision>
  </link>
  <link name="KeyHolders_v3_v1_1">
    <inertial>
      <origin rpy="0 0 0" xyz="1.1102230246251565e-16 -0.011000000000001618 0.0068557844147923985"/>
      <mass value="0.1127827330477343"/>
      <inertia ixx="9e-06" ixy="-0.0" ixz="-0.0" iyy="7.7e-05" iyz="-0.0" izz="8.2e-05"/>
    </inertial>
    <visual>
      <origin rpy="0 0 0" xyz="0.102 0.0 0.077325"/>
      <geometry>
        <mesh filename="file:///home/odinroast/Desktop/ros2_ws/install/ugv_description/share/ugv_description/meshes/KeyHolders_v3_v1_1.stl" scale="0.001 0.001 0.001"/>
      </geometry>
      <material name="silver"/>
    </visual>
    
  </link>
  <link name="3ButtonMount_v1_1">
    <inertial>
      <origin rpy="0 0 0" xyz="-0.0007243164609797015 0.00040991617311861295 0.020396118581781475"/>
      <mass value="0.1671642206432581"/>
      <inertia ixx="8.2e-05" ixy="-0.0" ixz="-3e-06" iyy="2.8e-05" iyz="1e-06" izz="7.2e-05"/>
    </inertial>
    <visual>
      <origin rpy="0 0 0" xyz="0.1695 0.0825 0.077325"/>
      <geometry>
        <mesh filename="file:///home/odinroast/Desktop/ros2_ws/install/ugv_description/share/ugv_description/meshes/3ButtonMount_v1_1.stl" scale="0.001 0.001 0.001"/>
      </geometry>
      <material name="silver"/>
    </visual>
    
  </link>
  <link name="RFD900urdf_v1_1">
    <inertial>
      <origin rpy="0 0 0" xyz="0.17686818743142876 0.014444185052039829 0.07383024977920567"/>
      <mass value="0.014123139557848672"/>
      <inertia ixx="1e-06" ixy="0.0" ixz="-0.0" iyy="2e-06" iyz="-0.0" izz="2e-06"/>
    </inertial>
    <visual>
      <origin rpy="0 0 0" xyz="0.354 0.089465 0.157674"/>
      <geometry>
        <mesh filename="file:///home/odinroast/Desktop/ros2_ws/install/ugv_description/share/ugv_description/meshes/RFD900urdf_v1_1.stl" scale="0.001 0.001 0.001"/>
      </geometry>
      <material name="silver"/>
    </visual>
        <collision>
      <origin rpy="0 0 0" xyz="0 0 0"/>
      <geometry>
        <box size="0.06 0.04 0.015"/>
      </geometry>
    </collision>
  </link>
  <link name="RFDAntenna_v1__1__1">
    <inertial>
      <origin rpy="0 0 0" xyz="-0.05327541437241906 -0.0005609684221182937 0.04387217526099607"/>
      <mass value="0.13898413435589144"/>
      <inertia ixx="0.00019" ixy="-2e-06" ixz="0.000125" iyy="0.000279" iyz="2e-06" izz="9.1e-05"/>
    </inertial>
    <visual>
      <origin rpy="0 0 0" xyz="0.200447 0.085518 0.0864"/>
      <geometry>
        <mesh filename="file:///home/odinroast/Desktop/ros2_ws/install/ugv_description/share/ugv_description/meshes/RFDAntenna_v1__1__1.stl" scale="0.001 0.001 0.001"/>
      </geometry>
      <material name="silver"/>
    </visual>
    
  </link>
  <link name="RFDAntenna_v1_1">
    <inertial>
      <origin rpy="0 0 0" xyz="-0.05327541437241906 -0.000561144988710946 0.04387217526099607"/>
      <mass value="0.13898413435589144"/>
      <inertia ixx="0.00019" ixy="-2e-06" ixz="0.000125" iyy="0.000279" iyz="2e-06" izz="9.1e-05"/>
    </inertial>
    <visual>
      <origin rpy="0 0 0" xyz="0.200447 0.064482 0.0864"/>
      <geometry>
        <mesh filename="file:///home/odinroast/Desktop/ros2_ws/install/ugv_description/share/ugv_description/meshes/RFDAntenna_v1_1.stl" scale="0.001 0.001 0.001"/>
      </geometry>
      <material name="silver"/>
    </visual>
    
  </link>
  <link name="MountingClipFinal_v1_1">
    <inertial>
      <origin rpy="0 0 0" xyz="6.021003140510572e-10 0.00012285664644182646 -0.01094859483785321"/>
      <mass value="0.015079084020968157"/>
      <inertia ixx="2e-06" ixy="-0.0" ixz="0.0" iyy="1e-06" iyz="0.0" izz="1e-06"/>
    </inertial>
    <visual>
      <origin rpy="0 0 0" xyz="-0.2795 0.0075 0.07325"/>
      <geometry>
        <mesh filename="file:///home/odinroast/Desktop/ros2_ws/install/ugv_description/share/ugv_description/meshes/MountingClipFinal_v1_1.stl" scale="0.001 0.001 0.001"/>
      </geometry>
      <material name="silver"/>
    </visual>
    
  </link>
  <link name="MountingClipFinal_v1__2__1">
    <inertial>
      <origin rpy="0 0 0" xyz="6.021003140510572e-10 -0.0001228566464420433 -0.01094859483785321"/>
      <mass value="0.015079084020968157"/>
      <inertia ixx="2e-06" ixy="0.0" ixz="0.0" iyy="1e-06" iyz="-0.0" izz="1e-06"/>
    </inertial>
    <visual>
      <origin rpy="0 0 0" xyz="-0.2795 0.1425 0.07325"/>
      <geometry>
        <mesh filename="file:///home/odinroast/Desktop/ros2_ws/install/ugv_description/share/ugv_description/meshes/MountingClipFinal_v1__2__1.stl" scale="0.001 0.001 0.001"/>
      </geometry>
      <material name="silver"/>
    </visual>
    
  </link>
  <link name="MountingClipFinal_v1__1__1">
    <inertial>
      <origin rpy="0 0 0" xyz="2.7755575615628914e-17 0.0001228566464418707 -0.010948401821885334"/>
      <mass value="0.015079084020968157"/>
      <inertia ixx="2e-06" ixy="-0.0" ixz="0.0" iyy="1e-06" iyz="0.0" izz="1e-06"/>
    </inertial>
    <visual>
      <origin rpy="0 0 0" xyz="0.0795 0.0075 0.0789"/>
      <geometry>
        <mesh filename="file:///home/odinroast/Desktop/ros2_ws/install/ugv_description/share/ugv_description/meshes/MountingClipFinal_v1__1__1.stl" scale="0.001 0.001 0.001"/>
      </geometry>
      <material name="silver"/>
    </visual>
    
  </link>
  <link name="MountingClipFinal_v1__3__1">
    <inertial>
      <origin rpy="0 0 0" xyz="-1.3877787807814457e-17 -0.00012285664644201555 -0.010948401821885334"/>
      <mass value="0.015079084020968157"/>
      <inertia ixx="2e-06" ixy="0.0" ixz="-0.0" iyy="1e-06" iyz="-0.0" izz="1e-06"/>
    </inertial>
    <visual>
      <origin rpy="0 0 0" xyz="0.0795 0.1425 0.0789"/>
      <geometry>
        <mesh filename="file:///home/odinroast/Desktop/ros2_ws/install/ugv_description/share/ugv_description/meshes/MountingClipFinal_v1__3__1.stl" scale="0.001 0.001 0.001"/>
      </geometry>
      <material name="silver"/>
    </visual>
    
  </link>
  <link name="Anker_737_Power_Bank_v2_1">
    <inertial>
      <origin rpy="0 0 0" xyz="0.00018600331285374694 1.3459909545779358e-05 0.024976668590988266"/>
      <mass value="3.244300003402338"/>
      <inertia ixx="0.001445" ixy="3e-06" ixz="-6e-06" iyy="0.007062" iyz="-0.0" izz="0.007191"/>
    </inertial>
    <visual>
      <origin rpy="0 0 0" xyz="-0.066 0.075 0.111"/>
      <geometry>
        <mesh filename="file:///home/odinroast/Desktop/ros2_ws/install/ugv_description/share/ugv_description/meshes/Anker_737_Power_Bank_v2_1.stl" scale="0.001 0.001 0.001"/>
      </geometry>
      <material name="silver"/>
    </visual>
    <collision>
      <origin rpy="0 0 0" xyz="0 0 0.025"/>
      <geometry>
        <box size="0.16 0.08 0.03"/>
      </geometry>
    </collision>
  </link>
  <link name="Insta360MountwithLidar_v1_1">
    <inertial>
      <origin rpy="0 0 0" xyz="-0.08620121608122361 0.0018031246909665094 0.02067739351315072"/>
      <mass value="0.39145830701811263"/>
      <inertia ixx="0.000407" ixy="2.3e-05" ixz="0.000185" iyy="0.000883" iyz="8e-06" izz="0.000749"/>
    </inertial>
    <visual>
      <origin rpy="0 0 0" xyz="-0.302 0.075 0.071675"/>
      <geometry>
        <mesh filename="file:///home/odinroast/Desktop/ros2_ws/install/ugv_description/share/ugv_description/meshes/Insta360MountwithLidar_v1_1.stl" scale="0.001 0.001 0.001"/>
      </geometry>
      <material name="silver"/>
    </visual>
        <collision>
      <origin rpy="0 0 0" xyz="0 0 0"/>
      <geometry>
        <box size="0.08 0.06 0.03"/>
      </geometry>
    </collision>
  </link>
  <link name="360Cam_v4_1">
    <inertial>
      <origin rpy="0 0 0" xyz="-1.4985461386229915e-05 2.292090469256658e-05 0.05820122616633873"/>
      <mass value="1.0655405086527066"/>
      <inertia ixx="0.001224" ixy="0.0" ixz="1e-06" iyy="0.001176" iyz="-1e-06" izz="0.000222"/>
    </inertial>
    <visual>
      <origin rpy="0 0 0" xyz="-0.1847 0.075 0.050175"/>
      <geometry>
        <mesh filename="file:///home/odinroast/Desktop/ros2_ws/install/ugv_description/share/ugv_description/meshes/360Cam_v4_1.stl" scale="0.001 0.001 0.001"/>
      </geometry>
      <material name="silver"/>
    </visual>
        <collision>
      <origin rpy="0 0 0" xyz="0 0 0"/>
      <geometry>
        <sphere radius="0.03"/>
      </geometry>
    </collision>
  </link>
  <link name="RPLidarC1_v1_1">
    <inertial>
      <origin rpy="0 0 0" xyz="-0.027912648043109 3.528651926237858e-06 0.017945081991656946"/>
      <mass value="0.7886321106213883"/>
      <inertia ixx="0.000269" ixy="0.0" ixz="-1e-06" iyy="0.000272" iyz="0.0" izz="0.000333"/>
    </inertial>
    <visual>
      <origin rpy="0 0 0" xyz="-0.302 0.075 0.064675"/>
      <geometry>
        <mesh filename="file:///home/odinroast/Desktop/ros2_ws/install/ugv_description/share/ugv_description/meshes/RPLidarC1_v1_1.stl" scale="0.001 0.001 0.001"/>
      </geometry>
      <material name="silver"/>
    </visual>
        <collision>
      <origin rpy="1.5708 0 0" xyz="0 0 0"/>
      <geometry>
        <cylinder radius="0.04" length="0.04"/>
      </geometry>
    </collision>
  </link>
  <link name="Chassis_1">
    <inertial>
      <origin rpy="0 0 0" xyz="-0.049170473747549126 0.07227739952469993 0.07007959503991401"/>
      <mass value="8.527219963844384"/>
      <inertia ixx="0.046219" ixy="0.000242" ixz="-0.018042" iyy="0.13905" iyz="5.9e-05" izz="0.163926"/>
    </inertial>
    <visual>
      <origin rpy="0 0 0" xyz="-0.134 0.1475 0.21525"/>
      <geometry>
        <mesh filename="file:///home/odinroast/Desktop/ros2_ws/install/ugv_description/share/ugv_description/meshes/Chassis_1.stl" scale="0.001 0.001 0.001"/>
      </geometry>
      <material name="silver"/>
    </visual>
    <collision>
      <origin rpy="0 0 0" xyz="-0.05 0.07 0.08"/>
      <geometry>
        <box size="0.38 0.28 0.04"/>
      </geometry>
    </collision>
  </link>
  <link name="Jetson_Nano_v1_1">
    <inertial>
      <origin rpy="0 0 0" xyz="-0.0024318044992874682 -0.0016233833475976789 0.012114861153457043"/>
      <mass value="0.5576736000183575"/>
      <inertia ixx="0.000337" ixy="-1e-06" ixz="4.1e-05" iyy="0.000338" iyz="3e-06" izz="0.000569"/>
    </inertial>
    <visual>
      <origin rpy="0 0 0" xyz="0.09325 0.096887 0.073325"/>
      <geometry>
        <mesh filename="file:///home/odinroast/Desktop/ros2_ws/install/ugv_description/share/ugv_description/meshes/Jetson_Nano_v1_1.stl" scale="0.001 0.001 0.001"/>
      </geometry>
      <material name="silver"/>
    </visual>
    
  </link>
  <link name="JetsonCaseTop_v1_1">
    <inertial>
      <origin rpy="0 0 0" xyz="0.0013908649786080612 -0.0640825625362274 0.02282384239942188"/>
      <mass value="0.6020214833179027"/>
      <inertia ixx="0.001081" ixy="-8.6e-05" ixz="-3.4e-05" iyy="0.000876" iyz="1.6e-05" izz="0.001827"/>
    </inertial>
    <visual>
      <origin rpy="0 0 0" xyz="0.093662 0.039887 0.073325"/>
      <geometry>
        <mesh filename="file:///home/odinroast/Desktop/ros2_ws/install/ugv_description/share/ugv_description/meshes/JetsonCaseTop_v1_1.stl" scale="0.001 0.001 0.001"/>
      </geometry>
      <material name="silver"/>
    </visual>
    
  </link>
  <link name="LIPOBattery_v2_1">
    <inertial>
      <origin rpy="0 0 0" xyz="1.9268691540952343e-07 -1.3877787807814457e-17 0.012000000000000052"/>
      <mass value="1.31409"/>
      <inertia ixx="0.000285" ixy="0.0" ixz="0.0" iyy="0.002694" iyz="-0.0" izz="0.002853"/>
    </inertial>
    <visual>
      <origin rpy="0 0 0" xyz="-0.066 0.075 0.135"/>
      <geometry>
        <mesh filename="file:///home/odinroast/Desktop/ros2_ws/install/ugv_description/share/ugv_description/meshes/LIPOBattery_v2_1.stl" scale="0.001 0.001 0.001"/>
      </geometry>
      <material name="silver"/>
    </visual>
    <collision>
      <origin rpy="0 0 0" xyz="0 0 0.012"/>
      <geometry>
        <box size="0.15 0.10 0.04"/>
      </geometry>
    </collision>
  </link>
  <link name="TOFSensor_v3_1">
    <inertial>
      <origin rpy="0 0 0" xyz="-0.001000000540000101 -4.2930317584871647e-07 -1.9999999996411777e-07"/>
      <mass value="0.006781887896042989"/>
      <inertia ixx="1e-06" ixy="0.0" ixz="0.0" iyy="0.0" iyz="-0.0" izz="0.0"/>
    </inertial>
    <visual>
      <origin rpy="0 0 0" xyz="0.179 0.027743 0.078112"/>
      <geometry>
        <mesh filename="file:///home/odinroast/Desktop/ros2_ws/install/ugv_description/share/ugv_description/meshes/TOFSensor_v3_1.stl" scale="0.001 0.001 0.001"/>
      </geometry>
      <material name="silver"/>
    </visual>
        <collision>
      <origin rpy="0 0 0" xyz="0 0 0"/>
      <geometry>
        <box size="0.02 0.015 0.01"/>
      </geometry>
    </collision>
  </link>
  <link name="LeftHub_1">
    <inertial>
      <origin rpy="0 0 0" xyz="-1.558126948913996e-05 0.012161091745128617 -0.06707623869249998"/>
      <mass value="0.7546189423866138"/>
      <inertia ixx="0.000578" ixy="-0.0" ixz="1e-06" iyy="0.000586" iyz="0.000107" izz="0.000234"/>
    </inertial>
    <visual>
      <origin rpy="0 0 0" xyz="-0.263789 0.004911 0.134519"/>
      <geometry>
        <mesh filename="file:///home/odinroast/Desktop/ros2_ws/install/ugv_description/share/ugv_description/meshes/LeftHub_1.stl" scale="0.001 0.001 0.001"/>
      </geometry>
      <material name="silver"/>
    </visual>
    <collision>
      <origin rpy="1.5708 0 0" xyz="0 0 -0.04"/>
      <geometry>
        <cylinder radius="0.03" length="0.06"/>
      </geometry>
    </collision>
  </link>
  <link name="RightHub__1">
    <inertial>
      <origin rpy="0 0 0" xyz="-1.5581269489250982e-05 -0.012161091298093979 -0.06707623869250007"/>
      <mass value="0.7546189423866142"/>
      <inertia ixx="0.000578" ixy="0.0" ixz="1e-06" iyy="0.000586" iyz="-0.000107" izz="0.000234"/>
    </inertial>
    <visual>
      <origin rpy="0 0 0" xyz="-0.263789 0.145089 0.134519"/>
      <geometry>
        <mesh filename="file:///home/odinroast/Desktop/ros2_ws/install/ugv_description/share/ugv_description/meshes/RightHub__1.stl" scale="0.001 0.001 0.001"/>
      </geometry>
      <material name="silver"/>
    </visual>
    <collision>
      <origin rpy="1.5708 0 0" xyz="0 0 -0.04"/>
      <geometry>
        <cylinder radius="0.03" length="0.06"/>
      </geometry>
    </collision>
  </link>
  <link name="FrontLeft_1">
    <inertial>
      <origin rpy="0 0 0" xyz="0.0 0.0 0.0"/>
      <mass value="0.1"/>
      <inertia ixx="0.0001" ixy="0.0" ixz="0.0" iyy="0.0002" iyz="0.0" izz="0.0001"/>
    </inertial>
    <visual>
      <origin rpy="0 0 0" xyz="-0.263789 -0.031089 0.213259"/>
      <geometry>
        <mesh filename="file:///home/odinroast/Desktop/ros2_ws/install/ugv_description/share/ugv_description/meshes/FrontLeft_1.stl" scale="0.001 0.001 0.001"/>
      </geometry>
      <material name="silver"/>
    </visual>
    <collision>
      <origin rpy="1.5708 0 0" xyz="0 0 0"/>
      <geometry>
        <cylinder radius="0.070" length="0.050"/>
      </geometry>
    </collision>
  </link>
  <link name="FrontRight_1">
    <inertial>
      <origin rpy="0 0 0" xyz="0.0 0.0 0.0"/>
      <mass value="0.1"/>
      <inertia ixx="0.0001" ixy="0.0" ixz="0.0" iyy="0.0002" iyz="0.0" izz="0.0001"/>
    </inertial>
    <visual>
      <origin rpy="0 0 0" xyz="-0.263789 0.181089 0.213259"/>
      <geometry>
        <mesh filename="file:///home/odinroast/Desktop/ros2_ws/install/ugv_description/share/ugv_description/meshes/FrontRight_1.stl" scale="0.001 0.001 0.001"/>
      </geometry>
      <material name="silver"/>
    </visual>
    <collision>
      <origin rpy="1.5708 0 0" xyz="0 0 0"/>
      <geometry>
        <cylinder radius="0.070" length="0.050"/>
      </geometry>
    </collision>
  </link>
  <link name="BackLeft_1">
    <inertial>
      <origin rpy="0 0 0" xyz="0.0 0.0 0.0"/>
      <mass value="0.1"/>
      <inertia ixx="0.0001" ixy="0.0" ixz="0.0" iyy="0.0002" iyz="0.0" izz="0.0001"/>
    </inertial>
    <visual>
      <origin rpy="0 0 0" xyz="0.071211 -0.031089 0.213259"/>
      <geometry>
        <mesh filename="file:///home/odinroast/Desktop/ros2_ws/install/ugv_description/share/ugv_description/meshes/BackLeft_1.stl" scale="0.001 0.001 0.001"/>
      </geometry>
      <material name="silver"/>
    </visual>
    <collision>
      <origin rpy="1.5708 0 0" xyz="0 0 0"/>
      <geometry>
        <cylinder radius="0.070" length="0.050"/>
      </geometry>
    </collision>
  </link>
  <link name="BackRight_1">
    <inertial>
      <origin rpy="0 0 0" xyz="0.0 0.0 0.0"/>
      <mass value="0.1"/>
      <inertia ixx="0.0001" ixy="0.0" ixz="0.0" iyy="0.0002" iyz="0.0" izz="0.0001"/>
    </inertial>
    <visual>
      <origin rpy="0 0 0" xyz="0.071211 0.181089 0.213259"/>
      <geometry>
        <mesh filename="file:///home/odinroast/Desktop/ros2_ws/install/ugv_description/share/ugv_description/meshes/BackRight_1.stl" scale="0.001 0.001 0.001"/>
      </geometry>
      <material name="silver"/>
    </visual>
    <collision>
      <origin rpy="1.5708 0 0" xyz="0 0 0"/>
      <geometry>
        <cylinder radius="0.070" length="0.050"/>
      </geometry>
    </collision>
  </link>
  <link name="GPSMount__1__v1_1">
    <inertial>
      <origin rpy="0 0 0" xyz="-0.021332153064071407 -0.007499991327375069 0.02673871532836188"/>
      <mass value="0.1455678711964743"/>
      <inertia ixx="8.3e-05" ixy="0.0" ixz="3e-05" iyy="7.3e-05" iyz="-0.0" izz="6.8e-05"/>
    </inertial>
    <visual>
      <origin rpy="0 0 0" xyz="-0.0075 0.0675 -0.00145"/>
      <geometry>
        <mesh filename="file:///home/odinroast/Desktop/ros2_ws/install/ugv_description/share/ugv_description/meshes/GPSMount__1__v1_1.stl" scale="0.001 0.001 0.001"/>
      </geometry>
      <material name="silver"/>
    </visual>
    
  </link>
  <link name="GPS_v1_1">
    <inertial>
      <origin rpy="0 0 0" xyz="0.0005012177154418637 0.010492718929645525 0.004731200250215797"/>
      <mass value="0.13196729677333102"/>
      <inertia ixx="4.7e-05" ixy="-0.0" ixz="0.0" iyy="4.3e-05" iyz="0.0" izz="8.4e-05"/>
    </inertial>
    <visual>
      <origin rpy="0 0 0" xyz="0.045886 0.08495 -0.05895"/>
      <geometry>
        <mesh filename="file:///home/odinroast/Desktop/ros2_ws/install/ugv_description/share/ugv_description/meshes/GPS_v1_1.stl" scale="0.001 0.001 0.001"/>
      </geometry>
      <material name="silver"/>
    </visual>
        <collision>
      <origin rpy="0 0 0" xyz="0 0 0"/>
      <geometry>
        <box size="0.055 0.055 0.015"/>
      </geometry>
    </collision>
  </link>
  <joint name="Rigid 2" type="fixed">
    <origin rpy="0 0 0" xyz="0.0075 -0.1425 -0.000125"/>
    <parent link="base_link"/>
    <child link="RightSupport_v1_1"/>
  </joint>
  <joint name="Rigid 3" type="fixed">
    <origin rpy="0 0 0" xyz="0.0075 -0.0075 -0.000125"/>
    <parent link="base_link"/>
    <child link="LeftSupport_v1_1"/>
  </joint>
  <joint name="Rigid 4" type="fixed">
    <origin rpy="0 0 0" xyz="0.152 0.0 -0.073125"/>
    <parent link="RightSupport_v1_1"/>
    <child link="Mounting_Plate_v3_v1_1"/>
  </joint>
  <joint name="Rigid 6" type="fixed">
    <origin rpy="0 0 0" xyz="-0.042 0.0 -0.0772"/>
    <parent link="RightSupport_v1_1"/>
    <child link="Mounting_Plate_v3_v1__1__1"/>
  </joint>
  <joint name="Rigid 7" type="fixed">
    <origin rpy="0 0 0" xyz="0.15 -0.075 0.00145"/>
    <parent link="base_link"/>
    <child link="FrontCover_v1_1"/>
  </joint>
  <joint name="Rigid 11" type="fixed">
    <origin rpy="0 0 0" xyz="0.0975 -0.1125 -0.000125"/>
    <parent link="base_link"/>
    <child link="CubeFC_v1_1"/>
  </joint>
  <joint name="Rigid 12" type="fixed">
    <origin rpy="0 0 0" xyz="0.12 0.12 0.0"/>
    <parent link="Mounting_Plate_v3_v1_1"/>
    <child link="FrontMountFull_v1_1"/>
  </joint>
  <joint name="Rigid 13" type="fixed">
    <origin rpy="0 0 0" xyz="0.024276 0.01375 0.001211"/>
    <parent link="FrontMountFull_v1_1"/>
    <child link="FrontLight_v1_1"/>
  </joint>
  <joint name="Rigid 14" type="fixed">
    <origin rpy="0 0 0" xyz="0.024276 -0.12125 0.001211"/>
    <parent link="FrontMountFull_v1_1"/>
    <child link="FrontLight_v1__1__1"/>
  </joint>
  <joint name="Rigid 15" type="fixed">
    <origin rpy="0 0 0" xyz="0.025598 -0.009276 -0.016879"/>
    <parent link="FrontMountFull_v1_1"/>
    <child link="Speaker_v1__1__1"/>
  </joint>
  <joint name="Rigid 16" type="fixed">
    <origin rpy="0 0 0" xyz="0.025598 -0.098224 -0.016879"/>
    <parent link="FrontMountFull_v1_1"/>
    <child link="Speaker_v1_1"/>
  </joint>
  <joint name="Rigid 19" type="fixed">
    <origin rpy="0 0 0" xyz="-0.06 0.045 0.0"/>
    <parent link="Mounting_Plate_v3_v1__1__1"/>
    <child link="JetsonCaseBottom_v1_1"/>
  </joint>
  <joint name="Rigid 22" type="fixed">
    <origin rpy="0 0 0" xyz="-0.0675 0.1425 0.0"/>
    <parent link="Mounting_Plate_v3_v1__1__1"/>
    <child link="KeyHolders_v3_v1_1"/>
  </joint>
  <joint name="Rigid 23" type="fixed">
    <origin rpy="0 0 0" xyz="-0.135 0.06 0.0"/>
    <parent link="Mounting_Plate_v3_v1__1__1"/>
    <child link="3ButtonMount_v1_1"/>
  </joint>
  <joint name="Rigid 24" type="fixed">
    <origin rpy="0 0 0" xyz="-0.3195 0.053035 -0.080349"/>
    <parent link="Mounting_Plate_v3_v1__1__1"/>
    <child link="RFD900urdf_v1_1"/>
  </joint>
  <joint name="Rigid 25" type="fixed">
    <origin rpy="0 0 0" xyz="0.153553 0.003947 0.071274"/>
    <parent link="RFD900urdf_v1_1"/>
    <child link="RFDAntenna_v1__1__1"/>
  </joint>
  <joint name="Rigid 26" type="fixed">
    <origin rpy="0 0 0" xyz="0.153553 0.024983 0.071274"/>
    <parent link="RFD900urdf_v1_1"/>
    <child link="RFDAntenna_v1_1"/>
  </joint>
  <joint name="Rigid 27" type="fixed">
    <origin rpy="0 0 0" xyz="0.12 0.135 0.0"/>
    <parent link="Mounting_Plate_v3_v1_1"/>
    <child link="MountingClipFinal_v1_1"/>
  </joint>
  <joint name="Rigid 28" type="fixed">
    <origin rpy="0 0 0" xyz="0.12 0.0 0.0"/>
    <parent link="Mounting_Plate_v3_v1_1"/>
    <child link="MountingClipFinal_v1__2__1"/>
  </joint>
  <joint name="Rigid 29" type="fixed">
    <origin rpy="0 0 0" xyz="-0.045 0.135 -0.001575"/>
    <parent link="Mounting_Plate_v3_v1__1__1"/>
    <child link="MountingClipFinal_v1__1__1"/>
  </joint>
  <joint name="Rigid 30" type="fixed">
    <origin rpy="0 0 0" xyz="-0.045 0.0 -0.001575"/>
    <parent link="Mounting_Plate_v3_v1__1__1"/>
    <child link="MountingClipFinal_v1__3__1"/>
  </joint>
  <joint name="Rigid 31" type="fixed">
    <origin rpy="0 0 0" xyz="0.0 0.0 0.024"/>
    <parent link="LIPOBattery_v2_1"/>
    <child link="Anker_737_Power_Bank_v2_1"/>
  </joint>
  <joint name="Rigid 38" type="fixed">
    <origin rpy="0 0 0" xyz="0.1425 0.0675 0.001575"/>
    <parent link="Mounting_Plate_v3_v1_1"/>
    <child link="Insta360MountwithLidar_v1_1"/>
  </joint>
  <joint name="Rigid 39" type="fixed">
    <origin rpy="0 0 0" xyz="-0.1173 0.0 0.0215"/>
    <parent link="Insta360MountwithLidar_v1_1"/>
    <child link="360Cam_v4_1"/>
  </joint>
  <joint name="Rigid 40" type="fixed">
    <origin rpy="0 0 0" xyz="0.0 0.0 0.007"/>
    <parent link="Insta360MountwithLidar_v1_1"/>
    <child link="RPLidarC1_v1_1"/>
  </joint>
  <joint name="Rigid 42" type="fixed">
    <origin rpy="0 0 0" xyz="0.1265 -0.14 -0.215125"/>
    <parent link="LeftSupport_v1_1"/>
    <child link="Chassis_1"/>
  </joint>
  <joint name="Rigid 44" type="fixed">
    <origin rpy="0 0 0" xyz="0.00125 0.000613 0.004"/>
    <parent link="JetsonCaseBottom_v1_1"/>
    <child link="Jetson_Nano_v1_1"/>
  </joint>
  <joint name="Rigid 45" type="fixed">
    <origin rpy="0 0 0" xyz="0.000838 0.057613 0.004"/>
    <parent link="JetsonCaseBottom_v1_1"/>
    <child link="JetsonCaseTop_v1_1"/>
  </joint>
  <joint name="Rigid 46" type="fixed">
    <origin rpy="0 0 0" xyz="-0.068 0.0725 0.08025"/>
    <parent link="Chassis_1"/>
    <child link="LIPOBattery_v2_1"/>
  </joint>
  <joint name="Rigid 51" type="fixed">
    <origin rpy="0 0 0" xyz="-0.1445 0.114757 -0.000787"/>
    <parent link="Mounting_Plate_v3_v1__1__1"/>
    <child link="TOFSensor_v3_1"/>
  </joint>
  <joint name="left_steering" type="revolute">
    <origin rpy="0 0 0" xyz="0.129789 0.142589 0.080731"/>
    <parent link="Chassis_1"/>
    <child link="LeftHub_1"/>
    <axis xyz="0.0 0.0 1.0"/>
    <limit lower="-0.7854" upper="0.7854" effort="10" velocity="2.0"/>
  </joint>
  <joint name="right_steering" type="revolute">
    <origin rpy="0 0 0" xyz="0.129789 0.002411 0.080731"/>
    <parent link="Chassis_1"/>
    <child link="RightHub__1"/>
    <axis xyz="0.0 0.0 1.0"/>
    <limit lower="-0.7854" upper="0.7854" effort="10" velocity="2.0"/>
  </joint>
  <joint name="front_left_wheel" type="continuous">
    <origin rpy="0 0 0" xyz="0.0 0.036 -0.07874"/>
    <parent link="LeftHub_1"/>
    <child link="FrontLeft_1"/>
    <axis xyz="0.0 1.0 0.0"/>
  </joint>
  <joint name="front_right_wheel" type="continuous">
    <origin rpy="0 0 0" xyz="0.0 -0.036 -0.07874"/>
    <parent link="RightHub__1"/>
    <child link="FrontRight_1"/>
    <axis xyz="0.0 1.0 0.0"/>
  </joint>
  <joint name="back_left_wheel" type="continuous">
    <origin rpy="0 0 0" xyz="-0.205211 0.178589 0.001991"/>
    <parent link="Chassis_1"/>
    <child link="BackLeft_1"/>
    <axis xyz="0.0 1.0 0.0"/>
  </joint>
  <joint name="back_right_wheel" type="continuous">
    <origin rpy="0 0 0" xyz="-0.205211 -0.033589 0.001991"/>
    <parent link="Chassis_1"/>
    <child link="BackRight_1"/>
    <axis xyz="0.0 1.0 0.0"/>
  </joint>
  <joint name="Rigid 58" type="fixed">
    <origin rpy="0 0 0" xyz="0.0075 -0.0675 0.00145"/>
    <parent link="base_link"/>
    <child link="GPSMount__1__v1_1"/>
  </joint>
  <joint name="Rigid 59" type="fixed">
    <origin rpy="0 0 0" xyz="-0.053386 -0.01745 0.0575"/>
    <parent link="GPSMount__1__v1_1"/>
    <child link="GPS_v1_1"/>
  </joint>
  <!-- Sensor Links for TF tree - Match Gazebo's auto-generated frame_ids -->
  <link name="ugv/camera_front_link/camera_front"/>
  <joint name="camera_front_joint" type="fixed">
    <origin rpy="0 0 0" xyz="0.022 0 0.093445"/>
    <parent link="360Cam_v4_1"/>
    <child link="ugv/camera_front_link/camera_front"/>
  </joint>
  <link name="ugv/camera_back_link/camera_back"/>
  <joint name="camera_back_joint" type="fixed">
    <origin rpy="0 0 3.14159" xyz="-0.022 0 0.093445"/>
    <parent link="360Cam_v4_1"/>
    <child link="ugv/camera_back_link/camera_back"/>
  </joint>
  <link name="ugv/lidar_2d_link/lidar_2d"/>
  <joint name="lidar_2d_joint" type="fixed">
    <origin rpy="0 0 0" xyz="-0.02780 0 0.03310"/>
    <parent link="RPLidarC1_v1_1"/>
    <child link="ugv/lidar_2d_link/lidar_2d"/>
  </joint>
  <link name="ugv/tof_link/tof_range"/>
  <joint name="tof_joint" type="fixed">
    <origin rpy="0 0 3.14159" xyz="0 0 0"/>
    <parent link="TOFSensor_v3_1"/>
    <child link="ugv/tof_link/tof_range"/>
  </joint>
  <link name="ugv/gps_link/gps"/>
  <joint name="gps_joint" type="fixed">
    <origin rpy="0 0 0" xyz="0 0.00995 0"/>
    <parent link="GPS_v1_1"/>
    <child link="ugv/gps_link/gps"/>
  </joint>
  <link name="ugv/imu0_link/imu0_sensor"/>
  <joint name="imu0_joint" type="fixed">
    <origin rpy="3.14159 0 0" xyz="0 0 0"/>
    <parent link="CubeFC_v1_1"/>
    <child link="ugv/imu0_link/imu0_sensor"/>
  </joint>
  <link name="ugv/imu1_link/imu1_sensor"/>
  <joint name="imu1_joint" type="fixed">
    <origin rpy="3.14159 0 0" xyz="0 0 0"/>
    <parent link="CubeFC_v1_1"/>
    <child link="ugv/imu1_link/imu1_sensor"/>
  </joint>
  <link name="ugv/imu2_link/imu2_sensor"/>
  <joint name="imu2_joint" type="fixed">
    <origin rpy="3.14159 0 0" xyz="0 0 0"/>
    <parent link="CubeFC_v1_1"/>
    <child link="ugv/imu2_link/imu2_sensor"/>
  </joint>
</robot>
